#VRML_SIM R2019a utf8
WorldInfo {
}
Viewpoint {
  orientation 0.8623306563761917 0.49315873205843475 0.11480550539204634 5.707155131715742
  position -0.4460992160328063 0.9450986275996981 1.5597858306543557
}
TexturedBackground {
}
TexturedBackgroundLight {
}
Floor {
}
Robot {
  translation 0 0.08 0
  children [
    DEF GR_BODY Group {
      children [
        DEF ROBOT_BODY Shape {
          appearance PBRAppearance {
            baseColor 0.9372549019607843 0.1607843137254902 0.1607843137254902
          }
          geometry DEF G_BODY Box {
            size 0.25 0.07 0.1
          }
        }
        Transform {
          translation 0.11 -0.05 0
          children [
            Shape {
              appearance PBRAppearance {
                baseColor 0.9882352941176471 0.9137254901960784 0.30980392156862746
                roughness 1
                metalness 0
              }
              geometry Sphere {
                radius 0.015
              }
            }
          ]
        }
      ]
    }
    DEF WHEEL1_JOINT HingeJoint {
      jointParameters HingeJointParameters {
        axis 0 0 1
        anchor -0.05 0 0.06
      }
      device [
        PositionSensor {
          name "encoder1"
          resolution 1
        }
        RotationalMotor {
          name "motor_right"
          maxVelocity 13.1
          maxTorque 0.4903
        }
      ]
      endPoint DEF WHEEL1 Solid {
        translation -0.05 0 0.06
        rotation 1 0 0 1.5707996938995745
        children [
          DEF SH_WHEEL Shape {
            appearance PBRAppearance {
              baseColor 0 0 0
              roughness 1
              metalness 0
            }
            geometry DEF G_WHEEL Cylinder {
              height 0.02
              radius 0.075
            }
          }
        ]
        boundingObject USE G_WHEEL
        physics Physics {
          mass 1
        }
      }
    }
    DEF WHEEL2_JOINT HingeJoint {
      jointParameters HingeJointParameters {
        axis 0 0 1
        anchor -0.05 0 -0.06
      }
      device [
        PositionSensor {
          name "encoder2"
          resolution 1
        }
        RotationalMotor {
          name "motor_left"
          maxVelocity 13.1
          maxTorque 0.4903
        }
      ]
      endPoint DEF WHEEL2 Solid {
        translation -0.05 0 -0.06
        rotation 1 0 0 1.5707996938995745
        children [
          USE SH_WHEEL
        ]
        name "solid(1)"
        boundingObject USE G_WHEEL
        physics Physics {
        }
      }
    }
    DistanceSensor {
      translation 0.125 0 0
      children [
        Shape {
          appearance PBRAppearance {
            baseColor 0.9882352941176471 0.9137254901960784 0.30980392156862746
          }
          geometry Box {
            size 0.02 0.01 0.01
          }
        }
      ]
      name "distance_sensor"
      lookupTable [
        0 0 0
        0.02 0 0
        11 1024 0
      ]
      resolution 0.003
    }
  ]
  boundingObject USE GR_BODY
  physics Physics {
    mass 1
  }
  controller "u2_exam"
}
Solid {
  translation 0.5100000000000001 0.15 0.5300000000000001
  children [
    Shape {
      appearance PBRAppearance {
        baseColor 0.6784313725490196 0.4980392156862745 0.6588235294117647
      }
      geometry DEF G_PUPPLEBOX Box {
        size 0.2 0.30000000000000004 0.1
      }
    }
  ]
  boundingObject USE G_PUPPLEBOX
}
